<mujoco>

    <worldbody>
        <body name="base" pos=".25 .25 .15">
            <joint type="free"/>
            <geom type="box" size=".12 .1 .05" rgba="1 .6 0 1"/>
            <geom type="box" size=".03 .1 .045" rgba="1 .4 0 0" pos="-.12 0 -.09"/>
            
            <site name="lidar_r" pos="0 0 .1" rgba="0 1 0 1" quat=".707 .707 0 0"/>
            <site name="lidar_l" pos="0 0 .1" rgba="0 1 0 1" quat=".707 -.707 0 0"/>
            <site name="lidar_l_45" pos="0 0 .1" rgba="0 1 0 1" quat=".2706 .2706 .6533 .6533"/>
            <site name="lidar_r_45" pos="0 0 .1" rgba="0 1 0 1" quat=".6533 .6533 .2706 .2706"/>
            <site name="lidar_f" pos="0 0 .1" rgba="0 1 0 1" quat=".5 .5 .5 .5"/>
            <site name="lidar_b" pos="0 0 .1" rgba="0 1 0 1" quat=".5 -.5 -.5 .5"/>

            <body name="wheel_left" pos="0 .075 -.05">
                <joint name="left" axis="0 1 0"/>
                <geom type="cylinder" size=".1" fromto="0 0 0 0 .05 0"/>
            </body>
            <body name="wheel_right" pos="0 -.075 -.05">
                <joint name="right" axis="0 1 0"/>
                <geom type="cylinder" size=".1" fromto="0 0 0 0 -.05 0"/>
            </body>
            <body name="ball" pos="-.1 0 -.14">
                <joint type="ball"/>
                <geom type="sphere" size=".01" rgba="0 0 1 1"/>
            </body>
            <body name="ball1" pos=".1 0 -.14">
                <joint type="ball"/>
                <geom type="sphere" size=".01" rgba="0 0 1 1"/>
            </body>
        </body>
    </worldbody>

    <actuator>
        <velocity name="motor_left" joint="left" kv="10" ctrlrange="-20 20"/>
        <velocity name="motor_right" joint="right" kv="10" ctrlrange="-20 20"/>
    </actuator>

    <sensor>
        <rangefinder name="lidar_r" site="lidar_r" cutoff="10"/>
        <rangefinder name="lidar_l" site="lidar_l" cutoff="10"/>
        <rangefinder name="lidar_l_45" site="lidar_l_45" cutoff="10"/>
        <rangefinder name="lidar_r_45" site="lidar_r_45" cutoff="10"/>
        <rangefinder name="lidar_f" site="lidar_f" cutoff="10"/>
        <rangefinder name="lidar_b" site="lidar_b" cutoff="10"/>
    </sensor>

</mujoco>